Workbook

Sheet INFORMATION
B3: DROMIC REPORT INFORMATION
B6: FIELD OFFICE | C6: FO 1
B7: DISASTER NAME: | C7: TD PILANDOK, SOUTHWEST MONSOON
B8: CONSOLIDATOR/S:
B9: TEMPLATE VERSION: | C9: 3.1
B10: INCIDENT REPORTING STATUS: | C10: On-Going
B11: DATE OF OCCURRENCE:
B12: NOTES / REMARKS:
H62: This Master Excel was created by JAN ERWIN ANDREW ONTANILLAS. Ginawa ko to para mapadali ang trabaho :) "Ang problema ay nasa TAO hindi sa TEKNOLOYIHA" Maraming Salamat po sa inyong lahat #10YearsinDSWD. Alrights Reserved 2024
I63: Master Excel Updated as of 4/13/2024 JEAIO V25.1
I64: Logs:
I68: Master Excel Updated as of 1/29/2024 JEAIO V24.2
I71: Upcoming Updates
H72: Master Excel Updated as of 1/23/2024 JEAIO V24.1
H73: Logs: | I73: Added ETC/CFW in every Region
I74: Added Grand Total Included Other Services in every Region
I75: Adjusted some Buggy formula within Regions
I76: Added Brgy Count in Every Region
I77: Added Listahan 2023 in Every Region
I78: Seperation of formula of HUC in every Region and not to be included in Province but direct to Region Totals
H79: Master Excel Updated as of 3/6/2024 JEAIO V25
I80: Major Changes on Master Excel
I81: Added SLP per Region
I82: Reorganized NFI alphabetically
I83: Renamed some part of COA
I84: Fixed issue on buggy formula
H86: Upcoming Updates
I87: No further update unless needed

Sheet Checker Sheet
E1: =_xludf.IFS(COUNTIFS($F$7:$X$7,"VALIDATE")>0,"VALIDATE",COUNTIFS($F$7:$X$7,"VALIDATE")=0,"CORRECT") -> #NAME?
F2: AFFECTED POPULATION | K2: DAMAGED HOUSES | L2: DISPLACEMENT | T2: SADD | V2: SADD | W2: COA
E3: REGION / PROVINCE / MUNICIPALITY | F3: Affected Persons > PSA | G3: Affected Brgy, Families, Person All Fields Required for Entry | H3: Affected Families >= Total Displaced Families (CUM) | I3: Affected Persons >= Total Displaced Persons (CUM) | J3: No Affected Families / Persons but with data on displaced / SADD / DH / COA | K3: Affected Families >= Damaged Houses | L3: Inside ECs Total Families (Now) vs Total Person (Now) | M3: Open ECs (NOW) vs Inside IDPs (NOW) | N3: Total Displaced=Inside+Outside (Families & Persons) CUM / NOW (Please separate column for CUM and NOW | O3: EC count - NOW vs CUM | P3: NOW < CUM (Families Inside EC) | Q3: NOW < CUM (Person Inside EC) | R3: NOW < CUM (Families Outside EC) | S3: NOW < CUM (Person Outside EC) | T3: Total Persons CUM vs Inside ECs Persons CUM | U3: Total Persons NOW vs Inside ECs Persons NOW | V3: Closed EC vs SADD NOW Persons | W3: FFPs vs Affected Families (1:10) | X3: Overall Checking
F7: =_xludf.IFS(COUNTIFS(F9:F143,"VALIDATE")>0,"VALIDATE",TRUE,"CORRECT") -> #NAME? | G7: =_xludf.IFS(COUNTIFS(G9:G143,"VALIDATE")>0,"VALIDATE",TRUE,"CORRECT") -> #NAME? | H7: =_xludf.IFS(COUNTIFS(H9:H143,"VALIDATE")>0,"VALIDATE",TRUE,"CORRECT") -> #NAME? | I7: =_xludf.IFS(COUNTIFS(I9:I143,"VALIDATE")>0,"VALIDATE",TRUE,"CORRECT") -> #NAME? | J7: =_xludf.IFS(COUNTIFS(J9:J143,"VALIDATE")>0,"VALIDATE",TRUE,"CORRECT") -> #NAME? | K7: =_xludf.IFS(COUNTIFS(K9:K143,"VALIDATE")>0,"VALIDATE",TRUE,"CORRECT") -> #NAME? | L7: =_xludf.IFS(COUNTIFS(L9:L143,"VALIDATE")>0,"VALIDATE",TRUE,"CORRECT") -> #NAME? | M7: =_xludf.IFS(COUNTIFS(M9:M143,"VALIDATE")>0,"VALIDATE",TRUE,"CORRECT") -> #NAME? | ... W7: =_xludf.IFS(COUNTIFS(W9:W143,"VALIDATE")>0,"VALIDATE",TRUE,"CORRECT") -> #NAME? | X7: =IF(COUNTIF(F7:W7,"VALIDATE")>0,"VALIDATE","CORRECT") -> CORRECT
X8: =IF(COUNTIF(F8:W8,"VALIDATE")>0,"VALIDATE","")
E9: GRAND TOTAL | F9: {=_xludf.IFS( 'FO 1 SUMMARY'!I8:I143<ABS('FO 1 SUMMARY'!L8:L143),"VALIDATE", TRUE,"")} -> #NAME? | G9: {=_xludf.IFS( (ABS('FO 1 SUMMARY'!J8:J143) + ABS('FO 1 SUMMARY'!K8:K143) + ABS('FO 1 SUMMARY'!L8:L143) > 0) * (ABS('FO 1 SUMMARY'!J8:J143) > 0) * (ABS('FO 1 SUMMARY'!K8:K143) > 0) * (ABS('FO 1 SUMMARY'!L8:L143) > 0), "", (ABS('FO 1 SUMMARY'!J8:J143) + ABS('FO 1 SUMMARY'!K8:K143) + ABS('FO 1 SUMMARY'!L8:L143) = 0) * (ABS('FO 1 SUMMARY'!J8:J143) = 0) * (ABS('FO 1 SUMMARY'!K8:K143) = 0) * (ABS('FO 1 SUMMARY'!L8:L143) = 0), "", TRUE,"VALIDATE" )} -> #NAME? | H9: {=_xludf.IFS('FO 1 SUMMARY'!K8:K143>='FO 1 SUMMARY'!AA8:AA143,"",TRUE,"VALIDATE")} -> #NAME? | I9: {=_xludf.IFS('FO 1 SUMMARY'!L8:L143>='FO 1 SUMMARY'!AC8:AC143,"",TRUE,"VALIDATE")} -> #NAME? | J9: {=_xludf.IFS(AND('FO 1 SUMMARY'!GF8:GF143="N/A",OR('FO 1 SUMMARY'!K8:K143>0,'FO 1 SUMMARY'!L9:L143>0)),"VALIDATE", AND('FO 1 SUMMARY'!GF8:GF143="DATA",OR('FO 1 SUMMARY'!K8:K143=0,'FO 1 SUMMARY'!L9:L143=0)),"VALIDATE", TRUE,"")} -> #NAME? | K9: {=_xludf.IFS('FO 1 SUMMARY'!K8:K143>='FO 1 SUMMARY'!EA8:EA143,"",TRUE,"VALIDATE")} -> #NAME? | L9: {=_xludf.IFS( 'FO 1 SUMMARY'!AB8:AB143=0 * 'FO 1 SUMMARY'!AD8:AD143=0,"", 'FO 1 SUMMARY'!AB8:AB143>0 * 'FO 1 SUMMARY'!AD8:AD143>0,"", 'FO 1 SUMMARY'!AB8:AB143>0 * 'FO 1 SUMMARY'!AD8:AD143<=0,"VALIDATE", 'FO 1 SUMMARY'!AB8:AB143<=0 * 'FO 1 SUMMARY'!AD8:AD143>0,"VALIDATE" )} -> #NAME? | M9: {=_xludf.IFS( ('FO 1 SUMMARY'!O8:O143 > 0) * ('FO 1 SUMMARY'!T8:T143 + 'FO 1 SUMMARY'!V8:V143) > 0, "", ('FO 1 SUMMARY'!O8:O143 = 0) * ('FO 1 SUMMARY'!T8:T143 + 'FO 1 SUMMARY'!V8:V143) = 0, "", ('FO 1 SUMMARY'!O8:O143 > 0) * ('FO 1 SUMMARY'!T8:T143 + 'FO 1 SUMMARY'!V8:V143) = 0, "VALIDATE", ('FO 1 SUMMARY'!O8:O143 = 0) * ('FO 1 SUMMARY'!T8:T143 + 'FO 1 SUMMARY'!V8:V143) > 0, "VALIDATE" )} -> #NAME? | N9: {=_xludf.IFS( (('FO 1 SUMMARY'!$U$8:$U143 + 'FO 1 SUMMARY'!$Y$8:$Y143 = 'FO 1 SUMMARY'!$AC$8:$AC143 ) * ( 'FO 1 SUMMARY'!$S$8:$S143 + 'FO 1 SUMMARY'!$W$8:$W143 = 'FO 1 SUMMARY'!$AA$8:$AA143)) = 1,"", TRUE,"VALIDATE" )} -> #NAME? | O9: {=_xludf.IFS( (ABS('FO 1 SUMMARY'!N8:N143) > ABS('FO 1 SUMMARY'!O8:O143)), "", ((ABS('FO 1 SUMMARY'!N8:N143)=0) * (ABS('FO 1 SUMMARY'!O8:O143)=0)), "", ((ABS('FO 1 SUMMARY'!N8:N143)>0 * ABS('FO 1 SUMMARY'!O8:O143)=0)), "", ((ABS('FO 1 SUMMARY'!N8:N143) = ABS('FO 1 SUMMARY'!O8:O143))), "", (ABS('FO 1 SUMMARY'!N8:N143) < ABS('FO 1 SUMMARY'!O8:O143)), "VALIDATE" )} -> #NAME? | P9: {=_xludf.IFS( 'FO 1 SUMMARY'!T9:T143>'FO 1 SUMMARY'!S9:S143,"VALIDATE", TRUE,"")} -> #NAME? | Q9: {=_xludf.IFS( 'FO 1 SUMMARY'!V9:V143>'FO 1 SUMMARY'!U9:U143,"VALIDATE", TRUE,"")} -> #NAME? | R9: {=_xludf.IFS( 'FO 1 SUMMARY'!X9:X143>'FO 1 SUMMARY'!W9:W143,"VALIDATE", TRUE,"")} -> #NAME? | S9: {=_xludf.IFS( 'FO 1 SUMMARY'!Z8:Z143>'FO 1 SUMMARY'!Y8:Y143,"VALIDATE", TRUE,"")} -> #NAME? | T9: {=IF('FO 1 SUMMARY'!BK8:BK143+'FO 1 SUMMARY'!BI8:BI143<='FO 1 SUMMARY'!U8:U143,"","VALIDATE")} | U9: {=IF('FO 1 SUMMARY'!BL8:BL143+'FO 1 SUMMARY'!BJ8:BJ143<='FO 1 SUMMARY'!V8:V143,"","VALIDATE")} | V9: {=_xludf.IFS( 'FO 1 SUMMARY'!O8:O143=0 * 'FO 1 SUMMARY'!BL8:BL143+'FO 1 SUMMARY'!BJ8:BJ143=0,"", 'FO 1 SUMMARY'!O8:O143>0 * 'FO 1 SUMMARY'!BL8:BL143+'FO 1 SUMMARY'!BJ8:BJ143>0,"", 'FO 1 SUMMARY'!O8:O143=0 * 'FO 1 SUMMARY'!BL8:BL143+'FO 1 SUMMARY'!BJ8:BJ143>0,"VALIDATE", 'FO 1 SUMMARY'!O8:O143>0 * 'FO 1 SUMMARY'!BL8:BL143+'FO 1 SUMMARY'!BJ8:BJ143=0,"VALIDATE", TRUE,"VALIDATE")} -> #NAME? | W9: {=_xludf.IFS( 'FO 1 SUMMARY'!K8:K143*10<ABS('FO 1 SUMMARY'!ED8:ED143),"VALIDATE", TRUE,"")} -> #NAME? | X9: =IF(COUNTIF(F9:W9,"VALIDATE")>0,"VALIDATE","")
B10: Region I (Ilocos Region) | E10: {=TRIM('FO 1 SUMMARY'!H9:H143)} -> REGION I | F10: #NAME? | G10: #NAME? | H10: #NAME? | I10: #NAME? | K10: #NAME? | L10: #NAME? | M10: #NAME? | N10: #NAME? | O10: #NAME? | P10: #NAME? | Q10: #NAME? | R10: #NAME? | S10: #NAME? | V10: #NAME? | W10: #NAME? | X10: =IF(COUNTIF(F10:W10,"VALIDATE")>0,"VALIDATE","")
B11: Region I (Ilocos Region) | E11: Ilocos Norte | F11: #NAME? | G11: #NAME? | H11: #NAME? | I11: #NAME? | K11: #NAME? | L11: #NAME? | M11: #NAME? | N11: #NAME? | O11: #NAME? | P11: #NAME? | Q11: #NAME? | R11: #NAME? | S11: #NAME? | V11: #NAME? | W11: #NAME? | X11: =IF(COUNTIF(F11:W11,"VALIDATE")>0,"VALIDATE","")
B12: Region I (Ilocos Region) | C12: Ilocos Norte | D12: PLGU Ilocos Norte | E12: PLGU Ilocos Norte | F12: #NAME? | G12: #NAME? | H12: #NAME? | I12: #NAME? | K12: #NAME? | L12: #NAME? | M12: #NAME? | N12: #NAME? | O12: #NAME? | P12: #NAME? | Q12: #NAME? | R12: #NAME? | S12: #NAME? | V12: #NAME? | W12: #NAME? | X12: =IF(COUNTIF(F12:W12,"VALIDATE")>0,"VALIDATE","")
B13: Region I (Ilocos Region) | C13: Ilocos Norte | D13: Adams | E13: Adams | F13: #NAME? | G13: #NAME? | H13: #NAME? | I13: #NAME? | K13: #NAME? | L13: #NAME? | M13: #NAME? | N13: #NAME? | O13: #NAME? | P13: #NAME? | Q13: #NAME? | R13: #NAME? | S13: #NAME? | V13: #NAME? | W13: #NAME? | X13: =IF(COUNTIF(F13:W13,"VALIDATE")>0,"VALIDATE","")
B14: Region I (Ilocos Region) | C14: Ilocos Norte | D14: Bacarra | E14: Bacarra | F14: #NAME? | G14: #NAME? | H14: #NAME? | I14: #NAME? | K14: #NAME? | L14: #NAME? | M14: #NAME? | N14: #NAME? | O14: #NAME? | P14: #NAME? | Q14: #NAME? | R14: #NAME? | S14: #NAME? | V14: #NAME? | W14: #NAME? | X14: =IF(COUNTIF(F14:W14,"VALIDATE")>0,"VALIDATE","")
B15: Region I (Ilocos Region) | C15: Ilocos Norte | D15: Badoc | E15: Badoc | F15: #NAME? | G15: #NAME? | H15: #NAME? | I15: #NAME? | K15: #NAME? | L15: #NAME? | M15: #NAME? | N15: #NAME? | O15: #NAME? | P15: #NAME? | Q15: #NAME? | R15: #NAME? | S15: #NAME? | V15: #NAME? | W15: #NAME? | X15: =IF(COUNTIF(F15:W15,"VALIDATE")>0,"VALIDATE","")
B16: Region I (Ilocos Region) | C16: Ilocos Norte | D16: Bangui | E16: Bangui | F16: #NAME? | G16: #NAME? | H16: #NAME? | I16: #NAME? | K16: #NAME? | L16: #NAME? | M16: #NAME? | N16: #NAME? | O16: #NAME? | P16: #NAME? | Q16: #NAME? | R16: #NAME? | S16: #NAME? | V16: #NAME? | W16: #NAME? | X16: =IF(COUNTIF(F16:W16,"VALIDATE")>0,"VALIDATE","")
B17: Region I (Ilocos Region) | C17: Ilocos Norte | D17: City of Batac | E17: City of Batac | F17: #NAME? | G17: #NAME? | H17: #NAME? | I17: #NAME? | K17: #NAME? | L17: #NAME? | M17: #NAME? | N17: #NAME? | O17: #NAME? | P17: #NAME? | Q17: #NAME? | R17: #NAME? | S17: #NAME? | V17: #NAME? | W17: #NAME? | X17: =IF(COUNTIF(F17:W17,"VALIDATE")>0,"VALIDATE","")
B18: Region I (Ilocos Region) | C18: Ilocos Norte | D18: Burgos | E18: Burgos | F18: #NAME? | G18: #NAME? | H18: #NAME? | I18: #NAME? | K18: #NAME? | L18: #NAME? | M18: #NAME? | N18: #NAME? | O18: #NAME? | P18: #NAME? | Q18: #NAME? | R18: #NAME? | S18: #NAME? | V18: #NAME? | W18: #NAME? | X18: =IF(COUNTIF(F18:W18,"VALIDATE")>0,"VALIDATE","")
B19: Region I (Ilocos Region) | C19: Ilocos Norte | D19: Carasi | E19: Carasi | F19: #NAME? | G19: #NAME? | H19: #NAME? | I19: #NAME? | K19: #NAME? | L19: #NAME? | M19: #NAME? | N19: #NAME? | O19: #NAME? | P19: #NAME? | Q19: #NAME? | R19: #NAME? | S19: #NAME? | V19: #NAME? | W19: #NAME? | X19: =IF(COUNTIF(F19:W19,"VALIDATE")>0,"VALIDATE","")
B20: Region I (Ilocos Region) | C20: Ilocos Norte | D20: Currimao | E20: Currimao | F20: #NAME? | G20: #NAME? | H20: #NAME? | I20: #NAME? | K20: #NAME? | L20: #NAME? | M20: #NAME? | N20: #NAME? | O20: #NAME? | P20: #NAME? | Q20: #NAME? | R20: #NAME? | S20: #NAME? | V20: #NAME? | W20: #NAME? | X20: =IF(COUNTIF(F20:W20,"VALIDATE")>0,"VALIDATE","")
B21: Region I (Ilocos Region) | C21: Ilocos Norte | D21: Dingras | E21: Dingras | F21: #NAME? | G21: #NAME? | H21: #NAME? | I21: #NAME? | K21: #NAME? | L21: #NAME? | M21: #NAME? | N21: #NAME? | O21: #NAME? | P21: #NAME? | Q21: #NAME? | R21: #NAME? | S21: #NAME? | V21: #NAME? | W21: #NAME? | X21: =IF(COUNTIF(F21:W21,"VALIDATE")>0,"VALIDATE","")
B22: Region I (Ilocos Region) | C22: Ilocos Norte | D22: Dumalneg | E22: Dumalneg | F22: #NAME? | G22: #NAME? | H22: #NAME? | I22: #NAME? | K22: #NAME? | L22: #NAME? | M22: #NAME? | N22: #NAME? | O22: #NAME? | P22: #NAME? | Q22: #NAME? | R22: #NAME? | S22: #NAME? | V22: #NAME? | W22: #NAME? | X22: =IF(COUNTIF(F22:W22,"VALIDATE")>0,"VALIDATE","")
B23: Region I (Ilocos Region) | C23: Ilocos Norte | D23: Banna | E23: Banna | F23: #NAME? | G23: #NAME? | H23: #NAME? | I23: #NAME? | K23: #NAME? | L23: #NAME? | M23: #NAME? | N23: #NAME? | O23: #NAME? | P23: #NAME? | Q23: #NAME? | R23: #NAME? | S23: #NAME? | V23: #NAME? | W23: #NAME? | X23: =IF(COUNTIF(F23:W23,"VALIDATE")>0,"VALIDATE","")
... B35: Region I (Ilocos Region) | C35: Ilocos Norte | D35: Vintar | E35: Vintar | F35: #NAME? | G35: #NAME? | H35: #NAME? | I35: #NAME? | K35: #NAME? | L35: #NAME? | M35: #NAME? | N35: #NAME? | O35: #NAME? | P35: #NAME? | Q35: #NAME? | R35: #NAME? | S35: #NAME? | V35: #NAME? | W35: #NAME? | X35: =IF(COUNTIF(F35:W35,"VALIDATE")>0,"VALIDATE","")
B36: Region I (Ilocos Region) | E36: Ilocos Sur | F36: #NAME? | G36: #NAME? | H36: #NAME? | I36: #NAME? | K36: #NAME? | L36: #NAME? | M36: #NAME? | N36: #NAME? | O36: #NAME? | P36: #NAME? | Q36: #NAME? | R36: #NAME? | S36: #NAME? | V36: #NAME? | W36: #NAME? | X36: =IF(COUNTIF(F36:W36,"VALIDATE")>0,"VALIDATE","")
B37: Region I (Ilocos Region) | C37: Ilocos Sur | D37: PLGU Ilocos Sur | E37: PLGU Ilocos Sur | F37: #NAME? | G37: #NAME? | H37: #NAME? | I37: #NAME? | K37: #NAME? | L37: #NAME? | M37: #NAME? | N37: #NAME? | O37: #NAME? | P37: #NAME? | Q37: #NAME? | R37: #NAME? | S37: #NAME? | V37: #NAME? | W37: #NAME? | X37: =IF(COUNTIF(F37:W37,"VALIDATE")>0,"VALIDATE","")
B38: Region I (Ilocos Region) | C38: Ilocos Sur | D38: Alilem | E38: Alilem | F38: #NAME? | G38: #NAME? | H38: #NAME? | I38: #NAME? | K38: #NAME? | L38: #NAME? | M38: #NAME? | N38: #NAME? | O38: #NAME? | P38: #NAME? | Q38: #NAME? | R38: #NAME? | S38: #NAME? | V38: #NAME? | W38: #NAME? | X38: =IF(COUNTIF(F38:W38,"VALIDATE")>0,"VALIDATE","")
B39: Region I (Ilocos Region) | C39: Ilocos Sur | D39: Banayoyo | E39: Banayoyo | F39: #NAME? | G39: #NAME? | H39: #NAME? | I39: #NAME? | K39: #NAME? | L39: #NAME? | M39: #NAME? | N39: #NAME? | O39: #NAME? | P39: #NAME? | Q39: #NAME? | R39: #NAME? | S39: #NAME? | V39: #NAME? | W39: #NAME? | X39: =IF(COUNTIF(F39:W39,"VALIDATE")>0,"VALIDATE","")
B40: Region I (Ilocos Region) | C40: Ilocos Sur | D40: Bantay | E40: Bantay | F40: #NAME? | G40: #NAME? | H40: #NAME? | I40: #NAME? | K40: #NAME? | L40: #NAME? | M40: #NAME? | N40: #NAME? | O40: #NAME? | P40: #NAME? | Q40: #NAME? | R40: #NAME? | S40: #NAME? | V40: #NAME? | W40: #NAME? | X40: =IF(COUNTIF(F40:W40,"VALIDATE")>0,"VALIDATE","")
B41: Region I (Ilocos Region) | C41: Ilocos Sur | D41: Burgos | E41: Burgos | F41: #NAME? | G41: #NAME? | H41: #NAME? | I41: #NAME? | K41: #NAME? | L41: #NAME? | M41: #NAME? | N41: #NAME? | O41: #NAME? | P41: #NAME? | Q41: #NAME? | R41: #NAME? | S41: #NAME? | V41: #NAME? | W41: #NAME? | X41: =IF(COUNTIF(F41:W41,"VALIDATE")>0,"VALIDATE","")
B42: Region I (Ilocos Region) | C42: Ilocos Sur | D42: Cabugao | E42: Cabugao | F42: #NAME? | G42: #NAME? | H42: #NAME? | I42: #NAME? | K42: #NAME? | L42: #NAME? | M42: #NAME? | N42: #NAME? | O42: #NAME? | P42: #NAME? | Q42: #NAME? | R42: #NAME? | S42: #NAME? | V42: #NAME? | W42: #NAME? | X42: =IF(COUNTIF(F42:W42,"VALIDATE")>0,"VALIDATE","")
B43: Region I (Ilocos Region) | C43: Ilocos Sur | D43: City of Candon | E43: City of Candon | F43: #NAME? | G43: #NAME? | H43: #NAME? | I43: #NAME? | K43: #NAME? | L43: #NAME? | M43: #NAME? | N43: #NAME? | O43: #NAME? | P43: #NAME? | Q43: #NAME? | R43: #NAME? | S43: #NAME? | V43: #NAME? | W43: #NAME? | X43: =IF(COUNTIF(F43:W43,"VALIDATE")>0,"VALIDATE","")
B44: Region I (Ilocos Region) | C44: Ilocos Sur | D44: Caoayan | E44: Caoayan | F44: #NAME? | G44: #NAME? | H44: #NAME? | I44: #NAME? | K44: #NAME? | L44: #NAME? | M44: #NAME? | N44: #NAME? | O44: #NAME? | P44: #NAME? | Q44: #NAME? | R44: #NAME? | S44: #NAME? | V44: #NAME? | W44: #NAME? | X44: =IF(COUNTIF(F44:W44,"VALIDATE")>0,"VALIDATE","")
B45: Region I (Ilocos Region) | C45: Ilocos Sur | D45: Cervantes | E45: Cervantes | F45: #NAME? | G45: #NAME? | H45: #NAME? | I45: #NAME? | K45: #NAME? | L45: #NAME? | M45: #NAME? | N45: #NAME? | O45: #NAME? | P45: #NAME? | Q45: #NAME? | R45: #NAME? | S45: #NAME? | V45: #NAME? | W45: #NAME? | X45: =IF(COUNTIF(F45:W45,"VALIDATE")>0,"VALIDATE","")
B46: Region I (Ilocos Region) | C46: Ilocos Sur | D46: Galimuyod | E46: Galimuyod | F46: #NAME? | G46: #NAME? | H46: #NAME? | I46: #NAME? | K46: #NAME? | L46: #NAME? | M46: #NAME? | N46: #NAME? | O46: #NAME? | P46: #NAME? | Q46: #NAME? | R46: #NAME? | S46: #NAME? | V46: #NAME? | W46: #NAME? | X46: =IF(COUNTIF(F46:W46,"VALIDATE")>0,"VALIDATE","")
B47: Region I (Ilocos Region) | C47: Ilocos Sur | D47: Gregorio del Pilar | E47: Gregorio del Pilar | F47: #NAME? | G47: #NAME? | H47: #NAME? | I47: #NAME? | K47: #NAME? | L47: #NAME? | M47: #NAME? | N47: #NAME? | O47: #NAME? | P47: #NAME? | Q47: #NAME? | R47: #NAME? | S47: #NAME? | V47: #NAME? | W47: #NAME? | X47: =IF(COUNTIF(F47:W47,"VALIDATE")>0,"VALIDATE","")
B48: Region I (Ilocos Region) | C48: Ilocos Sur | D48: Lidlidda | E48: Lidlidda | F48: #NAME? | G48: #NAME? | H48: #NAME? | I48: #NAME? | K48: #NAME? | L48: #NAME? | M48: #NAME? | N48: #NAME? | O48: #NAME? | P48: #NAME? | Q48: #NAME? | R48: #NAME? | S48: #NAME? | V48: #NAME? | W48: #NAME? | X48: =IF(COUNTIF(F48:W48,"VALIDATE")>0,"VALIDATE","")
... B71: Region I (Ilocos Region) | C71: Ilocos Sur | D71: City of Vigan | E71: City of Vigan | F71: #NAME? | G71: #NAME? | H71: #NAME? | I71: #NAME? | K71: #NAME? | L71: #NAME? | M71: #NAME? | N71: #NAME? | O71: #NAME? | P71: #NAME? | Q71: #NAME? | R71: #NAME? | S71: #NAME? | V71: #NAME? | W71: #NAME? | X71: =IF(COUNTIF(F71:W71,"VALIDATE")>0,"VALIDATE","")
B72: Region I (Ilocos Region) | E72: La Union | F72: #NAME? | G72: #NAME? | H72: #NAME? | I72: #NAME? | K72: #NAME? | L72: #NAME? | M72: #NAME? | N72: #NAME? | O72: #NAME? | P72: #NAME? | Q72: #NAME? | R72: #NAME? | S72: #NAME? | V72: #NAME? | W72: #NAME? | X72: =IF(COUNTIF(F72:W72,"VALIDATE")>0,"VALIDATE","")
B73: Region I (Ilocos Region) | C73: La Union | D73: PLGU La Union | E73: PLGU La Union | F73: #NAME? | G73: #NAME? | H73: #NAME? | I73: #NAME? | K73: #NAME? | L73: #NAME? | M73: #NAME? | N73: #NAME? | O73: #NAME? | P73: #NAME? | Q73: #NAME? | R73: #NAME? | S73: #NAME? | V73: #NAME? | W73: #NAME? | X73: =IF(COUNTIF(F73:W73,"VALIDATE")>0,"VALIDATE","")
B74: Region I (Ilocos Region) | C74: La Union | D74: Agoo | E74: Agoo | F74: #NAME? | G74: #NAME? | H74: #NAME? | I74: #NAME? | K74: #NAME? | L74: #NAME? | M74: #NAME? | N74: #NAME? | O74: #NAME? | P74: #NAME? | Q74: #NAME? | R74: #NAME? | S74: #NAME? | V74: #NAME? | W74: #NAME? | X74: =IF(COUNTIF(F74:W74,"VALIDATE")>0,"VALIDATE","")
B75: Region I (Ilocos Region) | C75: La Union | D75: Aringay | E75: Aringay | F75: #NAME? | G75: #NAME? | H75: #NAME? | I75: #NAME? | K75: #NAME? | L75: #NAME? | M75: #NAME? | N75: #NAME? | O75: #NAME? | P75: #NAME? | Q75: #NAME? | R75: #NAME? | S75: #NAME? | V75: #NAME? | W75: #NAME? | X75: =IF(COUNTIF(F75:W75,"VALIDATE")>0,"VALIDATE","")
B76: Region I (Ilocos Region) | C76: La Union | D76: Bacnotan | E76: Bacnotan | F76: #NAME? | G76: #NAME? | H76: #NAME? | I76: #NAME? | K76: #NAME? | L76: #NAME? | M76: #NAME? | N76: #NAME? | O76: #NAME? | P76: #NAME? | Q76: #NAME? | R76: #NAME? | S76: #NAME? | V76: #NAME? | W76: #NAME? | X76: =IF(COUNTIF(F76:W76,"VALIDATE")>0,"VALIDATE","")
...

Sheet (VIEW)Checker Sheet
E1: {='Checker Sheet'!E1:X143} -> #NAME? | F1: 0 | G1: 0 | H1: 0 | I1: 0 | J1: 0 | K1: 0 | L1: 0 | M1: 0 | N1: 0 | O1: 0 | P1: 0 | Q1: 0 | R1: 0 | S1: 0 | T1: 0 | U1: 0 | V1: 0 | W1: 0 | X1: 0
E2: 0 | F2: AFFECTED POPULATION | G2: 0 | H2: 0 | I2: 0 | J2: 0 | K2: DAMAGED HOUSES | L2: DISPLACEMENT | M2: 0 | N2: 0 | O2: 0 | P2: 0 | Q2: 0 | R2: 0 | S2: 0 | T2: SADD | U2: 0 | V2: SADD | W2: COA | X2: 0
E3: REGION / PROVINCE / MUNICIPALITY | F3: Affected Persons > PSA | G3: Affected Brgy, Families, Person All Fields Required for Entry | H3: Affected Families >= Total Displaced Families (CUM) | I3: Affected Persons >= Total Displaced Persons (CUM) | J3: No Affected Families / Persons but with data on displaced / SADD / DH / COA | K3: Affected Families >= Damaged Houses | L3: Inside ECs Total Families (Now) vs Total Person (Now) | M3: Open ECs (NOW) vs Inside IDPs (NOW) | N3: Total Displaced=Inside+Outside (Families & Persons) CUM / NOW (Please separate column for CUM and NOW | O3: EC count - NOW vs CUM | P3: NOW < CUM (Families Inside EC) | Q3: NOW < CUM (Person Inside EC) | R3: NOW < CUM (Families Outside EC) | S3: NOW < CUM (Person Outside EC) | T3: Total Persons CUM vs Inside ECs Persons CUM | U3: Total Persons NOW vs Inside ECs Persons NOW | V3: Closed EC vs SADD NOW Persons | W3: FFPs vs Affected Families (1:10) | X3: Overall Checking
E4: 0 | F4: 0 | G4: 0 | H4: 0 | I4: 0 | J4: 0 | K4: 0 | L4: 0 | M4: 0 | N4: 0 | O4: 0 | P4: 0 | Q4: 0 | R4: 0 | S4: 0 | T4: 0 | U4: 0 | V4: 0 | W4: 0 | X4: 0
E5: 0 | F5: 0 | G5: 0 | H5: 0 | I5: 0 | J5: 0 | K5: 0 | L5: 0 | M5: 0 | N5: 0 | O5: 0 | P5: 0 | Q5: 0 | R5: 0 | S5: 0 | T5: 0 | U5: 0 | V5: 0 | W5: 0 | X5: 0
E6: 0 | F6: 0 | G6: 0 | H6: 0 | I6: 0 | J6: 0 | K6: 0 | L6: 0 | M6: 0 | N6: 0 | O6: 0 | P6: 0 | Q6: 0 | R6: 0 | S6: 0 | T6: 0 | U6: 0 | V6: 0 | W6: 0 | X6: 0
E7: 0 | F7: #NAME? | G7: #NAME? | H7: #NAME? | I7: #NAME? | J7: #NAME? | K7: #NAME? | L7: #NAME? | M7: #NAME? | N7: #NAME? | O7: #NAME? | P7: #NAME? | Q7: #NAME? | R7: #NAME? | S7: #NAME? | T7: #NAME? | U7: #NAME? | V7: #NAME? | W7: #NAME? | X7: CORRECT
E8: 0 | F8: 0 | G8: 0 | H8: 0 | I8: 0 | J8: 0 | K8: 0 | L8: 0 | M8: 0 | N8: 0 | O8: 0 | P8: 0 | Q8: 0 | R8: 0 | S8: 0 | T8: 0 | U8: 0 | V8: 0 | W8: 0
E9: GRAND TOTAL | F9: #NAME? | G9: #NAME? | H9: #NAME? | I9: #NAME? | J9: #NAME? | K9: #NAME? | L9: #NAME? | M9: #NAME? | N9: #NAME? | O9: #NAME? | P9: #NAME? | Q9: #NAME? | R9: #NAME? | S9: #NAME? | V9: #NAME? | W9: #NAME?
E10: REGION I | F10: #NAME? | G10: #NAME? | H10: #NAME? | I10: #NAME? | J10: 0 | K10: #NAME? | L10: #NAME? | M10: #NAME? | N10: #NAME? | O10: #NAME? | P10: #NAME? | Q10: #NAME? | R10: #NAME? | S10: #NAME? | V10: #NAME? | W10: #NAME?
E11: Ilocos Norte | F11: #NAME? | G11: #NAME? | H11: #NAME? | I11: #NAME? | J11: 0 | K11: #NAME? | L11: #NAME? | M11: #NAME? | N11: #NAME? | O11: #NAME? | P11: #NAME? | Q11: #NAME? | R11: #NAME? | S11: #NAME? | V11: #NAME? | W11: #NAME?
E12: PLGU Ilocos Norte | F12: #NAME? | G12: #NAME? | H12: #NAME? | I12: #NAME? | J12: 0 | K12: #NAME? | L12: #NAME? | M12: #NAME? | N12: #NAME? | O12: #NAME? | P12: #NAME? | Q12: #NAME? | R12: #NAME? | S12: #NAME? | V12: #NAME? | W12: #NAME?
E13: Adams | F13: #NAME? | G13: #NAME? | H13: #NAME? | I13: #NAME? | J13: 0 | K13: #NAME? | L13: #NAME? | M13: #NAME? | N13: #NAME? | O13: #NAME? | P13: #NAME? | Q13: #NAME? | R13: #NAME? | S13: #NAME? | V13: #NAME? | W13: #NAME?
E14: Bacarra | F14: #NAME? | G14: #NAME? | H14: #NAME? | I14: #NAME? | J14: 0 | K14: #NAME? | L14: #NAME? | M14: #NAME? | N14: #NAME? | O14: #NAME? | P14: #NAME? | Q14: #NAME? | R14: #NAME? | S14: #NAME? | V14: #NAME? | W14: #NAME?
E15: Badoc | F15: #NAME? | G15: #NAME? | H15: #NAME? | I15: #NAME? | J15: 0 | K15: #NAME? | L15: #NAME? | M15: #NAME? | N15: #NAME? | O15: #NAME? | P15: #NAME? | Q15: #NAME? | R15: #NAME? | S15: #NAME? | V15: #NAME? | W15: #NAME?
E16: Bangui | F16: #NAME? | G16: #NAME? | H16: #NAME? | I16: #NAME? | J16: 0 | K16: #NAME? | L16: #NAME? | M16: #NAME? | N16: #NAME? | O16: #NAME? | P16: #NAME? | Q16: #NAME? | R16: #NAME? | S16: #NAME? | V16: #NAME? | W16: #NAME?
E17: City of Batac | F17: #NAME? | G17: #NAME? | H17: #NAME? | I17: #NAME? | J17: 0 | K17: #NAME? | L17: #NAME? | M17: #NAME? | N17: #NAME? | O17: #NAME? | P17: #NAME? | Q17: #NAME? | R17: #NAME? | S17: #NAME? | V17: #NAME? | W17: #NAME?
E18: Burgos | F18: #NAME? | G18: #NAME? | H18: #NAME? | I18: #NAME? | J18: 0 | K18: #NAME? | L18: #NAME? | M18: #NAME? | N18: #NAME? | O18: #NAME? | P18: #NAME? | Q18: #NAME? | R18: #NAME? | S18: #NAME? | V18: #NAME? | W18: #NAME?
E19: Carasi | F19: #NAME? | G19: #NAME? | H19: #NAME? | I19: #NAME? | J19: 0 | K19: #NAME? | L19: #NAME? | M19: #NAME? | N19: #NAME? | O19: #NAME? | P19: #NAME? | Q19: #NAME? | R19: #NAME? | S19: #NAME? | V19: #NAME? | W19: #NAME?
E20: Currimao | F20: #NAME? | G20: #NAME? | H20: #NAME? | I20: #NAME? | J20: 0 | K20: #NAME? | L20: #NAME? | M20: #NAME? | N20: #NAME? | O20: #NAME? | P20: #NAME? | Q20: #NAME? | R20: #NAME? | S20: #NAME? | V20: #NAME? | W20: #NAME?
E21: Dingras | F21: #NAME? | G21: #NAME? | H21: #NAME? | I21: #NAME? | J21: 0 | K21: #NAME? | L21: #NAME? | M21: #NAME? | N21: #NAME? | O21: #NAME? | P21: #NAME? | Q21: #NAME? | R21: #NAME? | S21: #NAME? | V21: #NAME? | W21: #NAME?
... E142: Laoac | F142: #NAME? | G142: #NAME? | H142: #NAME? | I142: #NAME? | J142: 0 | K142: #NAME? | L142: #NAME? | M142: #NAME? | N142: #NAME? | O142: #NAME? | P142: #NAME? | Q142: #NAME? | R142: #NAME? | S142: #NAME? | V142: #NAME? | W142: #NAME?
E143: City of Dagupan | F143: #NAME? | G143: #NAME? | H143: #NAME? | I143: #NAME? | J143: 0 | K143: #NAME? | L143: #NAME? | M143: #NAME? | N143: #NAME? | O143: #NAME? | P143: 0 | Q143: 0 | R143: 0 | S143: #NAME? | V143: #NAME? | W143: #NAME?

Sheet FO 1 SUMMARY
C1: Reg_Code_updated | D1: Prov_Code | E1: Mun_Code | F1: Reg_Name_Updated | G1: Pro_Name_updated | I1: PSA_2020 | J1: Brgy_Cnt | K1: Aff_Fam | L1: Aff_Per | M1: 4Ps_Fam | N1: EC_Cum | O1: EC_Now | S1: INFam_Cum | T1: INFam_Now | U1: INPer_Cum | V1: INPer_Now | W1: OUTFam_Cum | X1: OUTFam_Now | Y1: OUTPer_Cum | Z1: OUTPer_Now | AA1: DTOTFam_Cum | AB1: DTOTFam_Now | AC1: DTOTPer_Cum | AD1: DTOTPer_Now | AG1: M_Inf_CUM | AH1: F_Inf_NOW | AI1: F_Inf_CUM | AJ1: M_Inf_NOW | AK1: M_Tod_CUM | AL1: F_Tod_NOW | AM1: F_Tod_CUM | AN1: F_Tod_NOW | AO1: M_PSch_CUM | AP1: M_PSch_NOW | AQ1: F_PSch_CUM | AR1: F_PSch_NOW | AS1: M_Sch_CUM | AT1: M_Sch_NOW | AU1: F_Sch_CUM | AV1: F_Sch_NOW | AW1: M_Teen_CUM | AX1: M_Teen_NOW | AY1: F_Teen_CUM | AZ1: F_Teen_NOW | BA1: M_Adu_CUM | BB1: M_Adu_NOW | BC1: F_Adu_CUM | BD1: F_Adu_NOW | BE1: M_Snr_CUM | BF1: M_Snr_NOW | BG1: F_Snr_CUM | BH1: F_Snr_NOW | BI1: M_IDPs_CUM | BJ1: M_IDPs_NOW | BK1: F_IDPs_CUM | BL1: F_IDPs_NOW | BM1: PreW_CUM | BN1: PreW_NOW | BO1: Lac_CUM | BP1: Lac_NOW | BQ1: M_Min_CUM | BR1: M_Min_NOW | BS1: F_Min_CUM | BT1: F_Min_NOW | BY1: M_SolP_CUM | BZ1: M_SolP_NOW | CA1: F_SolP_CUM | CB1: F_SolP_NOW | CC1: M_PWDs_CUM | CD1: M_PWDs_NOW | CE1: F_PWDs_CUM | CF1: F_PWDs_NOW | CG1: M_IPs_CUM | CH1: M_IPs_NOW | CI1: F_IPs_CUM | CJ1: F_IPs_NOW | EA1: TOT_DHous | EB1: Tota_DHous | EC1: Par_DHous | ED1: DelFFPs_Q | EE1: DelFFPs_C | EF1: HEB_Q | EG1: HEB_C | EH1: RTEF_Q | EI1: RTEF_C | EJ1: SackRice_Q | EK1: SackRice_C | EM1: OFI_Q | EN1: OFI_C | EO1: ShelKit_Q | EP1: ShelKit_C | EQ1: HygKit_Q | ER1: HygKit_C | ES1: SlpKit_Q | ET1: SlpKit_C | EU1: KitchKit_Q | EV1: KitchKit_C | EW1: FamKit_Q | EX1: FamKit_C | EY1: WatCon_Q | EZ1: WatCon_C | FA1: LamSack_Q | FB1: LamSack_C | FC1: Tents_Q | FD1: Tents_C | FE1: MTents_Q | FF1: MTents_C | FH1: ONFI_Q | FI1: ONFI_C | FX1: DSWD | FY1: LGU | FZ1: NGOs | GA1: Others | GB1: Grand_TOT
H2: REGION / PROVINCE / MUNICIPALITY | I2: PSA 2024 | J2: NUMBER OF AFFECTED | N2: DISPLACEMENT DATA | AE2: NON IDPs | AG2: SEX & AGE DISTRIBUTION of IDPS INSIDE ECS | BM2: PREGNANT | BO2: LACTATING MOTHERS | BQ2: CHILD-HEADED FAMILY | BU2: SINGLE-HEADED FAMILY | BY2: SOLO PARENT | CC2: PERSONS W/ DISABILITY | CG2: INDIGENOUS PEOPLE (IPs) | CK2: 4Ps BENEFICIARIES | CO2: EVACUATION CENTER FACILITIES | DS2: Tents Deployed in Evacuation Centers | EA2: NO. OF DAMAGED HOUSES | ED2: DSWD FINANCIAL ASSISTANCE TOTAL + FNI
N3: NUMBER OF EVACUATION CENTERS (ECs) | P3: LATITUDE | Q3: LONGITUDE | R3: ORIGIN of IDPs | S3: NUMBER OF DISPLACED | ED3: DSWD | FW3: FINANCIAL ASSISTANCE TOTAL | FX3: DSWD FINANCIAL ASSISTANCE TOTAL + FNI | FY3: LGU | FZ3: NGOs | GA3: OTHERS | GB3: GRAND TOTAL (DSWD FNI + OTHER STAKEHOLDERS) | GC3: GRAND TOTAL (DSWD FNI & FINANCIAL ASSISTANCE + OTHER STAKEHOLDERS) | GD3: FILTER DISAGREGATED | GE3: HPMES DATA | GF3: FILTER SECTORAL
S4: INSIDE ECs | W4: OUTSIDE ECs | AA4: TOTAL | AE4: Families | AF4: Person | AG4: INFANT 0-6mos | AK4: TODDLERS 7 mos -2 y/o | AO4: PRESCHOOLERS 3-5 y/o | AS4: SCHOOL AGE 6-12 y/o | AW4: TEENAGE 13-17 y/o | BA4: ADULT 18-59 y/o | BE4: ELDERLY 60 and above | BI4: Total Number of IDPs Inside ECs | CO4: LATRINES | CW4: Child-Friendly Spaces | CY4: Women Friendly Spaces | DA4: Health Facility | DC4: Prayer Rooms | DE4: Community Kitchens | DG4: Handwashing Facility | DI4: Livestock Area | DK4: Camp Management Desk | DM4: Info Boards | DO4: Storage Area | DQ4: Laundry Space | ED4: Food Items | EO4: Non-Food Items | FJ4: FNI TOTAL | FK4: AICS | FN4: AKAP | FQ4: ECT | FS4: CFW | FU4: SLP
J5: Barangays | K5: Families | L5: Persons | M5: 4Ps Families | S5: Families | U5: Persons | W5: Families | Y5: Persons | AA5: Families | AC5: Persons | AG5: Male | AI5: Female | AK5: Male | AM5: Female | AO5: Male | AQ5: Female | AS5: Male | AU5: Female | AW5: Male | AY5: Female | BA5: Male | BC5: Female | BE5: Male | BG5: Female | BI5: Male | BK5: Female | BQ5: Male | BS5: Female | BU5: Male | BW5: Female | BY5: Male | CA5: Female | CC5: Male | CE5: Female | CG5: Male | CI5: Female | CK5: Male | CM5: Female | CO5: Compost Pit | CP5: Sealed | CQ5: TOILET | CT5: BATHING AREA | DS5: Family Tents | DU5: Modular Tents | DW5: Child Friendly Tents | DY5: Women Friendly Tents | ED5: FFP | EF5: HEB | EH5: RTEF | EJ5: RICE | EL5: Other Food Items | EO5: Family Kits | EQ5: Family Tent | ES5: Hygiene Kits | EU5: Kitchen Kits | EW5: Laminated Sacks | EY5: Modular Tent | FA5: Shelter Kits | FC5: Sleeping Kits | FE5: Water Container | FG5: OTHER Non-Food Items
N6: CUM | O6: NOW | S6: CUM | T6: NOW | U6: CUM | V6: NOW | W6: CUM | X6: NOW | Y6: CUM | Z6: NOW | AA6: CUM | AB6: NOW | AC6: CUM | AD6: NOW | AG6: CUM | AH6: NOW | AI6: CUM | AJ6: NOW | AK6: CUM | AL6: NOW | AM6: CUM | AN6: NOW | AO6: CUM | AP6: NOW | AQ6: CUM | AR6: NOW | AS6: CUM | AT6: NOW | AU6: CUM | AV6: NOW | AW6: CUM | AX6: NOW | AY6: CUM | AZ6: NOW | BA6: CUM | BB6: NOW | BC6: CUM | BD6: NOW | BE6: CUM | BF6: NOW | BG6: CUM | BH6: NOW | BI6: CUM | BJ6: NOW | BK6: CUM | BL6: NOW | BM6: CUM | BN6: NOW | BO6: CUM | BP6: NOW | BQ6: CUM | BR6: NOW | BS6: CUM | BT6: NOW | BU6: CUM | BV6: NOW | BW6: CUM | BX6: NOW | BY6: CUM | BZ6: NOW | CA6: CUM | CB6: NOW | CC6: CUM | CD6: NOW | CE6: CUM | CF6: NOW | CG6: CUM | CH6: NOW | CI6: CUM | CJ6: NOW | CK6: CUM | CL6: NOW | CM6: CUM | CN6: NOW | CQ6: Male | CR6: Female | CS6: Common | CT6: Male | CU6: Female | CV6: Common | CW6: CUM | CX6: NOW | CY6: CUM | CZ6: NOW | DA6: CUM | DB6: NOW | DC6: CUM | DD6: NOW | DE6: CUM | DF6: NOW | DG6: CUM | DH6: NOW | DI6: CUM | DJ6: NOW | DK6: CUM | DL6: NOW | DM6: CUM | DN6: NOW | DO6: CUM | DP6: NOW | DQ6: CUM | DR6: NOW | DS6: CUM | DT6: NOW | DU6: CUM | DV6: NOW | DW6: CUM | DX6: NOW | DY6: CUM | DZ6: NOW | EA6: Total | EB6: Totally | EC6: Partially | ED6: Quantity | EE6: Cost | EF6: Quantity | EG6: Cost | EH6: Quantity | EI6: Cost | EJ6: Quantity | EK6: Cost | EL6: Name | EM6: Quantity | EN6: Cost | EO6: Quantity | EP6: Cost | EQ6: Quantity | ER6: Cost | ES6: Quantity | ET6: Cost | EU6: Quantity | EV6: Cost | EW6: Quantity | EX6: Cost | EY6: Quantity | EZ6: Cost | FA6: Quantity | FB6: Cost | FC6: Quantity | FD6: Cost | FE6: Quantity | FF6: Cost | FG6: Name | FH6: Quantity | FI6: Cost | FK6: Number of Beneficiaries | FL6: Unit Cost | FM6: Cost | FN6: Number of Beneficiaries | FO6: Unit Cost | FP6: Cost | FQ6: Number of Beneficiaries | FR6: Cost | FS6: Number of Beneficiaries | FT6: Cost | FU6: Number of Beneficiaries | FV6: Cost
B8: 1 | H8: GRAND TOTAL | I8: =SUM(I9) -> 5489760 | J8: =SUM(J9) -> 15 | K8: =SUM(K9) -> 1094 | L8: =SUM(L9) -> 2709 | M8: =SUM(M9) -> 1 | N8: =SUM(N9) -> 0 | O8: =SUM(O9) -> 0 | R8: =SUM(R9) -> 0 | S8: =SUM(S9) -> 0 | T8: =SUM(T9) -> 0 | U8: =SUM(U9) -> 0 | V8: =SUM(V9) -> 0 | W8: =SUM(W9) -> 0 | X8: =SUM(X9) -> 0 | Y8: =SUM(Y9) -> 0 | ... FK8: =SUM(FK9) -> 0 | FM8: =SUM(FM9) -> 0 | FN8: =SUM(FN9) -> 0 | FP8: =SUM(FP9) -> 0 | FQ8: =SUM(FQ9) -> 0 | FR8: =SUM(FR9) -> 0 | FS8: =SUM(FS9) -> 0 | FT8: =SUM(FT9) -> 0 | FU8: =SUM(FU9) -> 0 | FV8: =SUM(FV9) -> 0 | FW8: =SUM(FW9) -> 0 | ... GC8: =SUM(GC9) -> 79564 | GD8: =IF(AG8+AI8+AK8+A8+AM8+AO8+AQ8+AS8+AU8+AW8+AY8+BA8+BC8+BE8+BG8>0,"DATA","N/A") -> N/A | GE8: {=IF(J8:J142 + L8:L142 + M8:M142 + Y8:Y142 + Z8:Z142 + AA8:AA142 + AB8:AB142 + BG8:BG142 + BH8:BH142 + BI8:BI142 + BJ8:BJ142 + CW8:CW142 + CX8:CX142 + EA8:EA142 + GB8:GB142 > 0, "DATA", "N/A")} -> DATA | GF8: =IF(BM8+BO8+BQ8+BS8+BY8+CA8+CC8+CE8+CG8+CI8<0,"DATA","N/A") -> N/A
B9: 2 | C9: PH0100000000 | F9: Region I (Ilocos Region) | H9: REGION I | I9: =SUM(I10,I35,I71,I93,I142) -> 5489760 | J9: =SUM(J10,J35,J71,J93,J142) -> 15 | K9: =SUM(K10,K35,K71,K93,K142) -> 1094 | L9: =SUM(L10,L35,L71,L93,L142) -> 2709 | M9: =SUM(M10,M35,M71,M93,M142) -> 1 | N9: =SUM(N10,N35,N71,N93,N142) -> 0 | O9: =SUM(O10,O35,O71,O93,O142) -> 0 | R9: =SUM(R10,R35,R71,R93,R142) -> 0 | S9: =SUM(S10,S35,S71,S93,S142) -> 0 | T9: =SUM(T10,T35,T71,T93,T142) -> 0 | U9: =SUM(U10,U35,U71,U93,U142) -> 0 | V9: =SUM(V10,V35,V71,V93,V142) -> 0 | W9: =SUM(W10,W35,W71,W93,W142) -> 0 | X9: =SUM(X10,X35,X71,X93,X142) -> 0 | Y9: =SUM(Y10,Y35,Y71,Y93,Y142) -> 0 | ... FK9: =SUM(FK10,FK35,FK71,FK93,FK142) -> 0 | FM9: =SUM(FM10,FM35,FM71,FM93,FM142) -> 0 | FN9: =SUM(FN10,FN35,FN71,FN93,FN142) -> 0 | FP9: =SUM(FP10,FP35,FP71,FP93,FP142) -> 0 | FQ9: =SUM(FQ10,FQ35,FQ71,FQ93,FQ142) -> 0 | FR9: =SUM(FR10,FR35,FR71,FR93,FR142) -> 0 | FS9: =SUM(FS10,FS35,FS71,FS93,FS142) -> 0 | FT9: =SUM(FT10,FT35,FT71,FT93,FT142) -> 0 | FU9: =SUM(FU10,FU35,FU71,FU93,FU142) -> 0 | FV9: =SUM(FV10,FV35,FV71,FV93,FV142) -> 0 | FW9: =SUM(FW10,FW35,FW71,FW93,FW142) -> 0 | ... GC9: =SUM(GC10,GC35,GC71,GC93,GC142) -> 79564 | GD9: =IF(AG9+AI9+AK9+A9+AM9+AO9+AQ9+AS9+AU9+AW9+AY9+BA9+BC9+BE9+BG9>0,"DATA","N/A") -> N/A | GE9: DATA | GF9: =IF(BM9+BO9+BQ9+BS9+BY9+CA9+CC9+CE9+CG9+CI9<0,"DATA","N/A") -> N/A
B10: 3 | C10: PH0100000000 | F10: Region I (Ilocos Region) | H10: Ilocos Norte | I10: =SUM(I11,I12,I13,I14,I15,I16,I17,I18,I19,I20,I21,I22,I23,I24,I25,I26,I27,I28,I29,I30,I31,I32,I33,I34) -> 618850 | J10: =SUM(J11:J34) -> 0 | K10: =SUM(K11:K34) -> 0 | L10: =SUM(L11:L34) -> 0 | M10: =SUM(M11:M34) -> 0 | N10: =SUM(N11:N34) -> 0 | O10: =SUM(O11:O34) -> 0 | R10: =SUM(R11:R34) -> 0 | S10: =SUM(S11:S34) -> 0 | T10: =SUM(T11:T34) -> 0 | U10: =SUM(U11:U34) -> 0 | V10: =SUM(V11:V34) -> 0 | W10: =SUM(W11:W34) -> 0 | X10: =SUM(X11:X34) -> 0 | Y10: =SUM(Y11:Y34) -> 0 | ... FK10: =SUM(FK11:FK34) -> 0 | FM10: =SUM(FM11:FM34) -> 0 | FN10: =SUM(FN11:FN34) -> 0 | FP10: =SUM(FP11:FP34) -> 0 | FQ10: =SUM(FQ11:FQ34) -> 0 | FR10: =SUM(FR11:FR34) -> 0 | FS10: =SUM(FS11:FS34) -> 0 | FT10: =SUM(FT11:FT34) -> 0 | FU10: =SUM(FU11:FU34) -> 0 | FV10: =SUM(FV11:FV34) -> 0 | FW10: =SUM(FW11:FW34) -> 0 | ... GC10: =SUM(GC11:GC34) -> 0 | GD10: =IF(AG10+AI10+AK10+A10+AM10+AO10+AQ10+AS10+AU10+AW10+AY10+BA10+BC10+BE10+BG10>0,"DATA","N/A") -> N/A | GE10: N/A | GF10: =IF(BM10+BO10+BQ10+BS10+BY10+CA10+CC10+CE10+CG10+CI10<0,"DATA","N/A") -> N/A
B11: 5 | C11: PH0100000000 | D11: PH0102800000 | E11: PLGU Ilocos Norte | F11: Region I (Ilocos Region) | G11: Ilocos Norte | H11: PLGU Ilocos Norte | J11: ='REGION I'!I12 -> 0 | K11: ='REGION I'!J12 -> 0 | L11: ='REGION I'!K12 -> 0 | M11: ='REGION I'!L12 -> 0 | N11: ='REGION I'!M12 -> 0 | O11: ='REGION I'!N12 -> 0 | P11: ='REGION I'!O12 -> 0 | Q11: ='REGION I'!P12 -> 0 | R11: ='REGION I'!T12 -> 0 | S11: ='REGION I'!U12 -> 0 | T11: ='REGION I'!V12 -> 0 | U11: ='REGION I'!W12 -> 0 | V11: ='REGION I'!X12 -> 0 | W11: ='REGION I'!Y12 -> 0 | X11: ='REGION I'!Z12 -> 0 | Y11: ='REGION I'!AA12 -> 0 | ... ED11: ='REGION I'!EF12 -> 0 | EE11: ='REGION I'!EH12 -> 0 | EF11: ='REGION I'!EI12 -> 0 | EG11: ='REGION I'!EK12 -> 0 | EH11: ='REGION I'!EL12 -> 0 | EI11: ='REGION I'!EN12 -> 0 | EJ11: ='REGION I'!EO12 -> 0 | EK11: ='REGION I'!EQ12 -> 0 | EL11: ='REGION I'!ER12 -> 0 | EM11: ='REGION I'!ES12 -> 0 | EN11: ='REGION I'!EU12 -> 0 | EO11: ='REGION I'!EV12 -> 0 | EP11: ='REGION I'!EX12 -> 0 | EQ11: ='REGION I'!EY12 -> 0 | ER11: ='REGION I'!FA12 -> 0 | ES11: ='REGION I'!FB12 -> 0 | ET11: ='REGION I'!FD12 -> 0 | EU11: ='REGION I'!FE12 -> 0 | EV11: ='REGION I'!FG12 -> 0 | EW11: ='REGION I'!FH12 -> 0 | EX11: ='REGION I'!FJ12 -> 0 | EY11: ='REGION I'!FK12 -> 0 | EZ11: ='REGION I'!FM12 -> 0 | FA11: ='REGION I'!FN12 -> 0 | FB11: ='REGION I'!FP12 -> 0 | FC11: ='REGION I'!FQ12 -> 0 | FD11: ='REGION I'!FS12 -> 0 | FE11: ='REGION I'!FT12 -> 0 | FF11: ='REGION I'!FV12 -> 0 | FG11: ='REGION I'!FW12 -> 0 | FH11: ='REGION I'!FX12 -> 0 | FI11: ='REGION I'!FZ12 -> 0 | FJ11: ='REGION I'!GA12 -> 0 | FK11: ='REGION I'!GB12 -> 0 | FL11: ='REGION I'!GC12 -> 0 | FM11: ='REGION I'!GD12 -> 0 | FN11: ='REGION I'!GE12 -> 0 | FO11: ='REGION I'!GF12 -> 0 | FP11: ='REGION I'!GG12 -> 0 | ... FV11: ='REGION I'!GM12 -> 0 | FW11: =SUM(FM11,FP11,FR11,FT11,FV11) -> 0 | FX11: ='REGION I'!GO12 -> 0 | FY11: ='REGION I'!GS12 -> 0 | FZ11: ='REGION I'!GT12 -> 0 | GA11: ='REGION I'!GU12 -> 0 | GB11: ='REGION I'!GV12 -> 0 | GC11: ='REGION I'!GW12 -> 0 | GD11: =IF(AG11+AI11+AK11+A11+AM11+AO11+AQ11+AS11+AU11+AW11+AY11+BA11+BC11+BE11+BG11>0,"DATA","N/A") -> N/A | GE11: N/A | GF11: =IF(BM11+BO11+BQ11+BS11+BY11+CA11+CC11+CE11+CG11+CI11<0,"DATA","N/A") -> N/A
B12: 4 | C12: PH0100000000 | D12: PH0102800000 | E12: PH0102801000 | F12: Region I (Ilocos Region) | G12: Ilocos Norte | H12: Adams | I12: {=VLOOKUP(H12:H34, 'REGION I'!$B$13:$GW219, COLUMN('REGION I'!F1)-1, FALSE)} -> 2279 | J12: {=VLOOKUP(H12:H34, 'REGION I'!$B$13:$GW219, COLUMN('REGION I'!I1)-1, FALSE)} -> 0 | K12: {=VLOOKUP(H12:H34, 'REGION I'!$B$13:$GW219, COLUMN('REGION I'!J1)-1, FALSE)} -> 0 | L12: {=VLOOKUP(H12:H34, 'REGION I'!$B$13:$GW219, COLUMN('REGION I'!K1)-1, FALSE)} -> 0 | M12: {=VLOOKUP(H12:H34, 'REGION I'!$B$13:$GW219, COLUMN('REGION I'!L1)-1, FALSE)} -> 0 | N12: {=VLOOKUP(H12:H34, 'REGION I'!$B$13:$GW219, COLUMN('REGION I'!M1)-1, FALSE)} -> 0 | O12: {=VLOOKUP($H12:$H34, 'REGION I'!$B$13:$GW219, COLUMN('REGION I'!N1)-1, FALSE)} -> 0 | P12: {=VLOOKUP($H12:$H34, 'REGION I'!$B$13:$GW219, COLUMN('REGION I'!O1)-1, FALSE)} -> 0 | Q12: {=VLOOKUP($H12:$H34, 'REGION I'!$B$13:$GW219, COLUMN('REGION I'!P1)-1, FALSE)} -> 0 | R12: {=VLOOKUP(H12:H34, 'REGION I'!$B$13:$GW219, COLUMN('REGION I'!T1)-1, FALSE)} -> 0 | S12: {=VLOOKUP(H12:H34, 'REGION I'!$B$13:$GW219, COLUMN('REGION I'!U1)-1, FALSE)} -> 0 | T12: {=VLOOKUP(H12:H34, 'REGION I'!$B$13:$GW219, COLUMN('REGION I'!V1)-1, FALSE)} -> 0 | U12: {=VLOOKUP(H12:H34, 'REGION I'!$B$13:$GW219, COLUMN('REGION I'!W1)-1, FALSE)} -> 0 | V12: {=VLOOKUP(H12:H34, 'REGION I'!$B$13:$GW219, COLUMN('REGION I'!X1)-1, FALSE)} -> 0 | W12: {=VLOOKUP(H12:H34, 'REGION I'!$B$13:$GW219, COLUMN('REGION I'!Y1)-1, FALSE)} -> 0 | X12: {=VLOOKUP(H12:H34, 'REGION I'!$B$13:$GW219, COLUMN('REGION I'!Z1)-1, FALSE)} -> 0 | Y12: {=VLOOKUP(H12:H34, 'REGION I'!$B$13:$GW219, COLUMN('REGION I'!AA1)-1, FALSE)} -> 0 | Z12: {=VLOOKUP(H12:H34, 'REGION I'!$B$13:$GW219, COLUMN('REGION I'!AB1)-1, FALSE)} -> 0 | AA12: {=VLOOKUP(H12:H34, 'REGION I'!$B$13:$GW219, COLUMN('REGION I'!AC1)-1, FALSE)} -> 0 | AB12: {=VLOOKUP(H12:H34, 'REGION I'!$B$13:$GW219, COLUMN('REGION I'!AD1)-1, FALSE)} -> 0 | AC12: {=VLOOKUP(H12:H34, 'REGION I'!$B$13:$GW219, COLUMN('REGION I'!AE1)-1, FALSE)} -> 0 | AD12: {=VLOOKUP(H12:H34, 'REGION I'!$B$13:$GW219, COLUMN('REGION I'!AF1)-1, FALSE)} -> 0 | AE12: {=VLOOKUP($H12:$H34, 'REGION I'!$B$13:$GW219, COLUMN('REGION I'!AG1)-1, FALSE)} -> 0 | AF12: {=VLOOKUP($H12:$H34, 'REGION I'!$B$13:$GW219, COLUMN('REGION I'!AH1)-1, FALSE)} -> 0 | AG12: {=VLOOKUP($H12:$H34, 'REGION I'!$B$13:$GW219, COLUMN('REGION I'!AI1)-1, FALSE)} -> 0 | AH12: {=VLOOKUP(H12:H34, 'REGION I'!$B$13:$GW219, COLUMN('REGION I'!AJ1)-1, FALSE)} -> 0 | AI12: {=VLOOKUP(H12:H34, 'REGION I'!$B$13:$GW219, COLUMN('REGION I'!AK1)-1, FALSE)} -> 0 | AJ12: {=VLOOKUP(H12:H34, 'REGION I'!$B$13:$GW219, COLUMN('REGION I'!AL1)-1, FALSE)} -> 0 | AK12: {=VLOOKUP(H12:H34, 'REGION I'!$B$13:$GW219, COLUMN('REGION I'!AM1)-1, FALSE)} -> 0 | AL12: {=VLOOKUP(H12:H34, 'REGION I'!$B$13:$GW219, COLUMN('REGION I'!AN1)-1, FALSE)} -> 0 | AM12: {=VLOOKUP(H12:H34, 'REGION I'!$B$13:$GW219, COLUMN('REGION I'!AO1)-1, FALSE)} -> 0 | AN12: {=VLOOKUP(H12:H34, 'REGION I'!$B$13:$GW219, COLUMN('REGION I'!AP1)-1, FALSE)} -> 0 | AO12: {=VLOOKUP(H12:H34, 'REGION I'!$B$13:$GW219, COLUMN('REGION I'!AQ1)-1, FALSE)} -> 0 | AP12: {=VLOOKUP(H12:H34, 'REGION I'!$B$13:$GW219, COLUMN('REGION I'!AR1)-1, FALSE)} -> 0 | AQ12: {=VLOOKUP(H12:H34, 'REGION I'!$B$13:$GW219, COLUMN('REGION I'!AS1)-1, FALSE)} -> 0 | AR12: {=VLOOKUP(H12:H34, 'REGION I'!$B$13:$GW219, COLUMN('REGION I'!AT1)-1, FALSE)} -> 0 | AS12: {=VLOOKUP(H12:H34, 'REGION I'!$B$13:$GW219, COLUMN('REGION I'!AU1)-1, FALSE)} -> 0 | AT12: {=VLOOKUP(H12:H34, 'REGION I'!$B$13:$GW219, COLUMN('REGION I'!AV1)-1, FALSE)} -> 0 | AU12: {=VLOOKUP(H12:H34, 'REGION I'!$B$13:$GW219, COLUMN('REGION I'!AW1)-1, FALSE)} -> 0 | AV12: {=VLOOKUP(H12:H34, 'REGION I'!$B$13:$GW219, COLUMN('REGION I'!AX1)-1, FALSE)} -> 0 | AW12: {=VLOOKUP(H12:H34, 'REGION I'!$B$13:$GW219, COLUMN('REGION I'!AY1)-1, FALSE)} -> 0 | AX12: {=VLOOKUP(H12:H34, 'REGION I'!$B$13:$GW219, COLUMN('REGION I'!AZ1)-1, FALSE)} -> 0 | AY12: {=VLOOKUP(H12:H34, 'REGION I'!$B$13:$GW219, COLUMN('REGION I'!BA1)-1, FALSE)} -> 0 | AZ12: {=VLOOKUP(H12:H34, 'REGION I'!$B$13:$GW219, COLUMN('REGION I'!BB1)-1, FALSE)} -> 0 | BA12: {=VLOOKUP(H12:H34, 'REGION I'!$B$13:$GW219, COLUMN('REGION I'!BC1)-1, FALSE)} -> 0 | BB12: {=VLOOKUP(H12:H34, 'REGION I'!$B$13:$GW219, COLUMN('REGION I'!BD1)-1, FALSE)} -> 0 | BC12: {=VLOOKUP(H12:H34, 'REGION I'!$B$13:$GW219, COLUMN('REGION I'!BE1)-1, FALSE)} -> 0 | BD12: {=VLOOKUP(H12:H34, 'REGION I'!$B$13:$GW219, COLUMN('REGION I'!BF1)-1, FALSE)} -> 0 | BE12: {=VLOOKUP(H12:H34, 'REGION I'!$B$13:$GW219, COLUMN('REGION I'!BG1)-1, FALSE)} -> 0 | BF12: {=VLOOKUP(H12:H34, 'REGION I'!$B$13:$GW219, COLUMN('REGION I'!BH1)-1, FALSE)} -> 0 | BG12: {=VLOOKUP(H12:H34, 'REGION I'!$B$13:$GW219, COLUMN('REGION I'!BI1)-1, FALSE)} -> 0 | BH12: {=VLOOKUP(H12:H34, 'REGION I'!$B$13:$GW219, COLUMN('REGION I'!BJ1)-1, FALSE)} -> 0 | BI12: {=VLOOKUP(H12:H34, 'REGION I'!$B$13:$GW219, COLUMN('REGION I'!BK1)-1, FALSE)} -> 0 | BJ12: {=VLOOKUP(H12:H34, 'REGION I'!$B$13:$GW219, COLUMN('REGION I'!BL1)-1, FALSE)} -> 0 | BK12: {=VLOOKUP(H12:H34, 'REGION I'!$B$13:$GW219, COLUMN('REGION I'!BM1)-1, FALSE)} -> 0 | BL12: {=VLOOKUP(H12:H34, 'REGION I'!$B$13:$GW219, COLUMN('REGION I'!BN1)-1, FALSE)} -> 0 | BM12: {=VLOOKUP(H12:H34, 'REGION I'!$B$13:$GW219, COLUMN('REGION I'!BO1)-1, FALSE)} -> 0 | BN12: {=VLOOKUP(H12:H34, 'REGION I'!$B$13:$GW219, COLUMN('REGION I'!BP1)-1, FALSE)} -> 0 | BO12: {=VLOOKUP(H12:H34, 'REGION I'!$B$13:$GW219, COLUMN('REGION I'!BQ1)-1, FALSE)} -> 0 | BP12: {=VLOOKUP(H12:H34, 'REGION I'!$B$13:$GW219, COLUMN('REGION I'!BR1)-1, FALSE)} -> 0 | BQ12: {=VLOOKUP(H12:H34, 'REGION I'!$B$13:$GW219, COLUMN('REGION I'!BS1)-1, FALSE)} -> 0 | BR12: {=VLOOKUP(H12:H34, 'REGION I'!$B$13:$GW219, COLUMN('REGION I'!BT1)-1, FALSE)} -> 0 | BS12: {=VLOOKUP(H12:H34, 'REGION I'!$B$13:$GW219, COLUMN('REGION I'!BU1)-1, FALSE)} -> 0 | BT12: {=VLOOKUP(H12:H34, 'REGION I'!$B$13:$GW219, COLUMN('REGION I'!BV1)-1, FALSE)} -> 0 | BU12: {=VLOOKUP(H12:H34, 'REGION I'!$B$13:$GW219, COLUMN('REGION I'!BW1)-1, FALSE)} -> 0 | BV12: {=VLOOKUP(H12:H34, 'REGION I'!$B$13:$GW219, COLUMN('REGION I'!BX1)-1, FALSE)} -> 0 | BW12: {=VLOOKUP(H12:H34, 'REGION I'!$B$13:$GW219, COLUMN('REGION I'!BY1)-1, FALSE)} -> 0 | BX12: {=VLOOKUP(H12:H34, 'REGION I'!$B$13:$GW219, COLUMN('REGION I'!BZ1)-1, FALSE)} -> 0 | BY12: {=VLOOKUP(H12:H34, 'REGION I'!$B$13:$GW219, COLUMN('REGION I'!CA1)-1, FALSE)} -> 0 | BZ12: {=VLOOKUP(H12:H34, 'REGION I'!$B$13:$GW219, COLUMN('REGION I'!CB1)-1, FALSE)} -> 0 | CA12: {=VLOOKUP(H12:H34, 'REGION I'!$B$13:$GW219, COLUMN('REGION I'!CC1)-1, FALSE)} -> 0 | CB12: {=VLOOKUP(H12:H34, 'REGION I'!$B$13:$GW219, COLUMN('REGION I'!CD1)-1, FALSE)} -> 0 | CC12: {=VLOOKUP(H12:H34, 'REGION I'!$B$13:$GW219, COLUMN('REGION I'!CE1)-1, FALSE)} -> 0 | CD12: {=VLOOKUP(H12:H34, 'REGION I'!$B$13:$GW219, COLUMN('REGION I'!CF1)-1, FALSE)} -> 0 | CE12: {=VLOOKUP(H12:H34, 'REGION I'!$B$13:$GW219, COLUMN('REGION I'!CG1)-1, FALSE)} -> 0 | CF12: {=VLOOKUP(H12:H34, 'REGION I'!$B$13:$GW219, COLUMN('REGION I'!CH1)-1, FALSE)} -> 0 | CG12: {=VLOOKUP(H12:H34, 'REGION I'!$B$13:$GW219, COLUMN('REGION I'!CI1)-1, FALSE)} -> 0 | CH12: {=VLOOKUP(H12:H34, 'REGION I'!$B$13:$GW219, COLUMN('REGION I'!CJ1)-1, FALSE)} -> 0 | CI12: {=VLOOKUP(H12:H34, 'REGION I'!$B$13:$GW219, COLUMN('REGION I'!CK1)-1, FALSE)} -> 0 | CJ12: {=VLOOKUP(H12:H34, 'REGION I'!$B$13:$GW219, COLUMN('REGION I'!CL1)-1, FALSE)} -> 0 | CK12: {=VLOOKUP(H12:H34, 'REGION I'!$B$13:$GW219, COLUMN('REGION I'!CM1)-1, FALSE)} -> 0 | CL12: {=VLOOKUP(H12:H34, 'REGION I'!$B$13:$GW219, COLUMN('REGION I'!CN1)-1, FALSE)} -> 0 | CM12: {=VLOOKUP(H12:H34, 'REGION I'!$B$13:$GW219, COLUMN('REGION I'!CO1)-1, FALSE)} -> 0 | CN12: {=VLOOKUP(H12:H34, 'REGION I'!$B$13:$GW219, COLUMN('REGION I'!CP1)-1, FALSE)} -> 0 | CO12: {=VLOOKUP($H12:$H34, 'REGION I'!$B$13:$GW219, COLUMN('REGION I'!CQ1)-1, FALSE)} -> 0 | CP12: {=VLOOKUP($H12:$H34, 'REGION I'!$B$13:$GW219, COLUMN('REGION I'!CR1)-1, FALSE)} -> 0 | CQ12: {=VLOOKUP($H12:$H34, 'REGION I'!$B$13:$GW219, COLUMN('REGION I'!CS1)-1, FALSE)} -> 0 | CR12: {=VLOOKUP($H12:$H34, 'REGION I'!$B$13:$GW219, COLUMN('REGION I'!CT1)-1, FALSE)} -> 0 | CS12: {=VLOOKUP($H12:$H34, 'REGION I'!$B$13:$GW219, COLUMN('REGION I'!CU1)-1, FALSE)} -> 0 | CT12: {=VLOOKUP($H12:$H34, 'REGION I'!$B$13:$GW219, COLUMN('REGION I'!CV1)-1, FALSE)} -> 0 | CU12: {=VLOOKUP($H12:$H34, 'REGION I'!$B$13:$GW219, COLUMN('REGION I'!CW1)-1, FALSE)} -> 0 | CV12: {=VLOOKUP($H12:$H34, 'REGION I'!$B$13:$GW219, COLUMN('REGION I'!CX1)-1, FALSE)} -> 0 | ... DZ12: {=VLOOKUP($H12:$H34, 'REGION I'!$B$13:$GW219, COLUMN('REGION I'!EB1)-1, FALSE)} -> 0 | EA12: {=VLOOKUP(H12:H34, 'REGION I'!$B$13:$GW219, COLUMN('REGION I'!EC1)-1, FALSE)} -> 0 | EB12: {=VLOOKUP(H12:H34, 'REGION I'!$B$13:$GW219, COLUMN('REGION I'!ED1)-1, FALSE)} -> 0 | EC12: {=VLOOKUP(H12:H34, 'REGION I'!$B$13:$GW219, COLUMN('REGION I'!EE1)-1, FALSE)} -> 0 | ED12: {=VLOOKUP(H12:H34, 'REGION I'!$B$13:$GW219, COLUMN('REGION I'!EF1)-1, FALSE)} -> 0 | EE12: {=VLOOKUP(H12:H34, 'REGION I'!$B$13:$GW219, COLUMN('REGION I'!EH1)-1, FALSE)} -> 0 | EF12: {=VLOOKUP(H12:H34, 'REGION I'!$B$13:$GW219, COLUMN('REGION I'!EI1)-1, FALSE)} -> 0 | EG12: {=VLOOKUP(H12:H34, 'REGION I'!$B$13:$GW219, COLUMN('REGION I'!EK1)-1, FALSE)} -> 0 | EH12: {=VLOOKUP(H12:H34, 'REGION I'!$B$13:$GW219, COLUMN('REGION I'!EL1)-1, FALSE)} -> 0 | EI12: {=VLOOKUP(H12:H34, 'REGION I'!$B$13:$GW219, COLUMN('REGION I'!EN1)-1, FALSE)} -> 0 | EJ12: {=VLOOKUP(H12:H34, 'REGION I'!$B$13:$GW219, COLUMN('REGION I'!EO1)-1, FALSE)} -> 0 | EK12: {=VLOOKUP(H12:H34, 'REGION I'!$B$13:$GW219, COLUMN('REGION I'!EQ1)-1, FALSE)} -> 0 | EL12: {=VLOOKUP(H12:H34, 'REGION I'!$B$13:$GW219, COLUMN('REGION I'!ER1)-1, FALSE)} -> 0 | EM12: {=VLOOKUP(H12:H34, 'REGION I'!$B$13:$GW219, COLUMN('REGION I'!ES1)-1, FALSE)} -> 0 | EN12: {=VLOOKUP(H12:H34, 'REGION I'!$B$13:$GW219, COLUMN('REGION I'!EU1)-1, FALSE)} -> 0 | EO12: {=VLOOKUP(H12:H34, 'REGION I'!$B$13:$GW219, COLUMN('REGION I'!EV1)-1, FALSE)} -> 0 | EP12: {=VLOOKUP(H12:H34, 'REGION I'!$B$13:$GW219, COLUMN('REGION I'!EX1)-1, FALSE)} -> 0 | EQ12: {=VLOOKUP(H12:H34, 'REGION I'!$B$13:$GW219, COLUMN('REGION I'!EY1)-1, FALSE)} -> 0 | ER12: {=VLOOKUP(H12:H34, 'REGION I'!$B$13:$GW219, COLUMN('REGION I'!FA1)-1, FALSE)} -> 0 | ES12: {=VLOOKUP(H12:H34, 'REGION I'!$B$13:$GW219, COLUMN('REGION I'!FB1)-1, FALSE)} -> 0 | ET12: {=VLOOKUP(H12:H34, 'REGION I'!$B$13:$GW219, COLUMN('REGION I'!FD1)-1, FALSE)} -> 0 | EU12: {=VLOOKUP(H12:H34, 'REGION I'!$B$13:$GW219, COLUMN('REGION I'!FE1)-1, FALSE)} -> 0 | EV12: {=VLOOKUP(H12:H34, 'REGION I'!$B$13:$GW219, COLUMN('REGION I'!FG1)-1, FALSE)} -> 0 | EW12: {=VLOOKUP(H12:H34, 'REGION I'!$B$13:$GW219, COLUMN('REGION I'!FH1)-1, FALSE)} -> 0 | EX12: {=VLOOKUP(H12:H34, 'REGION I'!$B$13:$GW219, COLUMN('REGION I'!FJ1)-1, FALSE)} -> 0 | EY12: {=VLOOKUP(H12:H34, 'REGION I'!$B$13:$GW219, COLUMN('REGION I'!FK1)-1, FALSE)} -> 0 | EZ12: {=VLOOKUP(H12:H34, 'REGION I'!$B$13:$GW219, COLUMN('REGION I'!FM1)-1, FALSE)} -> 0 | FA12: {=VLOOKUP(H12:H34, 'REGION I'!$B$13:$GW219, COLUMN('REGION I'!FN1)-1, FALSE)} -> 0 | FB12: {=VLOOKUP(H12:H34, 'REGION I'!$B$13:$GW219, COLUMN('REGION I'!FP1)-1, FALSE)} -> 0 | FC12: {=VLOOKUP(H12:H34, 'REGION I'!$B$13:$GW219, COLUMN('REGION I'!FQ1)-1, FALSE)} -> 0 | FD12: {=VLOOKUP(H12:H34, 'REGION I'!$B$13:$GW219, COLUMN('REGION I'!FS1)-1, FALSE)} -> 0 | FE12: {=VLOOKUP(H12:H34, 'REGION I'!$B$13:$GW219, COLUMN('REGION I'!FT1)-1, FALSE)} -> 0 | FF12: {=VLOOKUP(H12:H34, 'REGION I'!$B$13:$GW219, COLUMN('REGION I'!FV1)-1, FALSE)} -> 0 | FG12: {=VLOOKUP(H12:H34, 'REGION I'!$B$13:$GW219, COLUMN('REGION I'!FW1)-1, FALSE)} -> 0 | FH12: {=VLOOKUP(H12:H34, 'REGION I'!$B$13:$GW219, COLUMN('REGION I'!FX1)-1, FALSE)} -> 0 | FI12: {=VLOOKUP(H12:H34, 'REGION I'!$B$13:$GW219, COLUMN('REGION I'!FZ1)-1, FALSE)} -> 0 | FJ12: {=VLOOKUP(H12:H34, 'REGION I'!$B$13:$GW219, COLUMN('REGION I'!GA1)-1, FALSE)} -> 0 | FK12: {=VLOOKUP(H12:H34, 'REGION I'!$B$13:$GW219, COLUMN('REGION I'!GB1)-1, FALSE)} -> 0 | FL12: {=VLOOKUP(H12:H34, 'REGION I'!$B$13:$GW219, COLUMN('REGION I'!GC1)-1, FALSE)} -> 0 | FM12: {=VLOOKUP(H12:H34, 'REGION I'!$B$13:$GW219, COLUMN('REGION I'!GD1)-1, FALSE)} -> 0 | FN12: {=VLOOKUP(H12:H34, 'REGION I'!$B$13:$GW219, COLUMN('REGION I'!GE1)-1, FALSE)} -> 0 | FO12: {=VLOOKUP(H12:H34, 'REGION I'!$B$13:$GW219, COLUMN('REGION I'!GF1)-1, FALSE)} -> 0 | FP12: {=VLOOKUP(H12:H34, 'REGION I'!$B$13:$GW219, COLUMN('REGION I'!GG1)-1, FALSE)} -> 0 | FQ12: {=VLOOKUP(H12:H34, 'REGION I'!$B$13:$GW219, COLUMN('REGION I'!GH1)-1, FALSE)} -> 0 | FR12: {=VLOOKUP(H12:H34, 'REGION I'!$B$13:$GW219, COLUMN('REGION I'!GI1)-1, FALSE)} -> 0 | FS12: {=VLOOKUP(H12:H34, 'REGION I'!$B$13:$GW219, COLUMN('REGION I'!GJ1)-1, FALSE)} -> 0 | FT12: {=VLOOKUP(H12:H34, 'REGION I'!$B$13:$GW219, COLUMN('REGION I'!GK1)-1, FALSE)} -> 0 | FU12: {=VLOOKUP(H12:H34, 'REGION I'!$B$13:$GW219, COLUMN('REGION I'!GL1)-1, FALSE)} -> 0 | FV12: {=VLOOKUP(H12:H34, 'REGION I'!$B$13:$GW219, COLUMN('REGION I'!GM1)-1, FALSE)} -> 0 | FW12: {=VLOOKUP(H12:H34, 'REGION I'!$B$13:$GW219, COLUMN('REGION I'!GN1)-1, FALSE)} -> 0 | FX12: {=VLOOKUP(H12:H34, 'REGION I'!$B$13:$GW219, COLUMN('REGION I'!GO1)-1, FALSE)} -> 0 | FY12: {=VLOOKUP(H12:H34, 'REGION I'!$B$13:$GW219, COLUMN('REGION I'!GS1)-1, FALSE)} -> 0 | FZ12: {=VLOOKUP(H12:H34, 'REGION I'!$B$13:$GW219, COLUMN('REGION I'!GT1)-1, FALSE)} -> 0 | GA12: {=VLOOKUP(H12:H34, 'REGION I'!$B$13:$GW219, COLUMN('REGION I'!GU1)-1, FALSE)} -> 0 | GB12: {=VLOOKUP(H12:H34, 'REGION I'!$B$13:$GW219, COLUMN('REGION I'!GV1)-1, FALSE)} -> 0 | GC12: {=VLOOKUP(H12:H34, 'REGION I'!$B$13:$GW219, COLUMN('REGION I'!GW1)-1, FALSE)} -> 0 | GD12: =IF(AG12+AI12+AK12+A12+AM12+AO12+AQ12+AS12+AU12+AW12+AY12+BA12+BC12+BE12+BG12>0,"DATA","N/A") -> N/A | GE12: N/A | GF12: =IF(BM12+BO12+BQ12+BS12+BY12+CA12+CC12+CE12+CG12+CI12<0,"DATA","N/A") -> N/A
B13: 4 | C13: PH0100000000 | D13: PH0102800000 | E13: PH0102802000 | F13: Region I (Ilocos Region) | G13: Ilocos Norte | H13: Bacarra | I13: 32734 | J13: 0 | K13: 0 | L13: 0 | M13: 0 | N13: 0 | O13: 0 | P13: 0 | Q13: 0 | R13: 0 | S13: 0 | T13: 0 | U13: 0 | V13: 0 | W13: 0 | X13: 0 | Y13: 0 | Z13: 0 | AA13: 0 | AB13: 0 | AC13: 0 | AD13: 0 | AE13: 0 | AF13: 0 | AG13: 0 | AH13: 0 | AI13: 0 | AJ13: 0 | AK13: 0 | AL13: 0 | AM13: 0 | AN13: 0 | AO13: 0 | AP13: 0 | AQ13: 0 | AR13: 0 | AS13: 0 | AT13: 0 | AU13: 0 | AV13: 0 | AW13: 0 | AX13: 0 | AY13: 0 | AZ13: 0 | BA13: 0 | BB13: 0 | BC13: 0 | BD13: 0 | BE13: 0 | BF13: 0 | BG13: 0 | BH13: 0 | BI13: 0 | BJ13: 0 | BK13: 0 | BL13: 0 | BM13: 0 | BN13: 0 | BO13: 0 | BP13: 0 | BQ13: 0 | BR13: 0 | BS13: 0 | BT13: 0 | BU13: 0 | BV13: 0 | BW13: 0 | BX13: 0 | BY13: 0 | BZ13: 0 | CA13: 0 | CB13: 0 | CC13: 0 | CD13: 0 | CE13: 0 | CF13: 0 | CG13: 0 | CH13: 0 | CI13: 0 | CJ13: 0 | CK13: 0 | CL13: 0 | CM13: 0 | CN13: 0 | CO13: 0 | CP13: 0 | CQ13: 0 | CR13: 0 | CS13: 0 | CT13: 0 | CU13: 0 | CV13: 0 | CW13: 0 | CX13: 0 | CY13: 0 | CZ13: 0 | DA13: 0 | DB13: 0 | DC13: 0 | DD13: 0 | DE13: 0 | DF13: 0 | DG13: 0 | DH13: 0 | DI13: 0 | DJ13: 0 | DK13: 0 | DL13: 0 | DM13: 0 | DN13: 0 | DO13: 0 | DP13: 0 | DQ13: 0 | DR13: 0 | DS13: 0 | DT13: 0 | DU13: 0 | DV13: 0 | DW13: 0 | DX13: 0 | DY13: 0 | DZ13: 0 | EA13: 0 | EB13: 0 | EC13: 0 | ED13: 0 | EE13: 0 | EF13: 0 | EG13: 0 | EH13: 0 | EI13: 0 | EJ13: 0 | EK13: 0 | EL13: 0 | EM13: 0 | EN13: 0 | EO13: 0 | EP13: 0 | EQ13: 0 | ER13: 0 | ES13: 0 | ET13: 0 | EU13: 0 | EV13: 0 | EW13: 0 | EX13: 0 | EY13: 0 | EZ13: 0 | FA13: 0 | FB13: 0 | FC13: 0 | FD13: 0 | FE13: 0 | FF13: 0 | FG13: 0 | FH13: 0 | FI13: 0 | FJ13: 0 | FK13: 0 | FL13: 0 | FM13: 0 | FN13: 0 | FO13: 0 | FP13: 0 | FQ13: 0 | FR13: 0 | FS13: 0 | FT13: 0 | FU13: 0 | FV13: 0 | FW13: 0 | FX13: 0 | FY13: 0 | FZ13: 0 | GA13: 0 | GB13: 0 | GC13: 0 | GD13: =IF(AG13+AI13+AK13+A13+AM13+AO13+AQ13+AS13+AU13+AW13+AY13+BA13+BC13+BE13+BG13>0,"DATA","N/A") -> N/A | GE13: N/A | GF13: =IF(BM13+BO13+BQ13+BS13+BY13+CA13+CC13+CE13+CG13+CI13<0,"DATA","N/A") -> N/A
B14: 4 | C14: PH0100000000 | D14: PH0102800000 | E14: PH0102803000 | F14: Region I (Ilocos Region) | G14: Ilocos Norte | H14: Badoc | I14: 32832 | J14: 0 | K14: 0 | L14: 0 | M14: 0 | N14: 0 | O14: 0 | P14: 0 | Q14: 0 | R14: 0 | S14: 0 | T14: 0 | U14: 0 | V14: 0 | W14: 0 | X14: 0 | Y14: 0 | Z14: 0 | AA14: 0 | AB14: 0 | AC14: 0 | AD14: 0 | AE14: 0 | AF14: 0 | AG14: 0 | AH14: 0 | AI14: 0 | AJ14: 0 | AK14: 0 | AL14: 0 | AM14: 0 | AN14: 0 | AO14: 0 | AP14: 0 | AQ14: 0 | AR14: 0 | AS14: 0 | AT14: 0 | AU14: 0 | AV14: 0 | AW14: 0 | AX14: 0 | AY14: 0 | AZ14: 0 | BA14: 0 | BB14: 0 | BC14: 0 | BD14: 0 | BE14: 0 | BF14: 0 | BG14: 0 | BH14: 0 | BI14: 0 | BJ14: 0 | BK14: 0 | BL14: 0 | BM14: 0 | BN14: 0 | BO14: 0 | BP14: 0 | BQ14: 0 | BR14: 0 | BS14: 0 | BT14: 0 | BU14: 0 | BV14: 0 | BW14: 0 | BX14: 0 | BY14: 0 | BZ14: 0 | CA14: 0 | CB14: 0 | CC14: 0 | CD14: 0 | CE14: 0 | CF14: 0 | CG14: 0 | CH14: 0 | CI14: 0 | CJ14: 0 | CK14: 0 | CL14: 0 | CM14: 0 | CN14: 0 | CO14: 0 | CP14: 0 | CQ14: 0 | CR14: 0 | CS14: 0 | CT14: 0 | CU14: 0 | CV14: 0 | CW14: 0 | CX14: 0 | CY14: 0 | CZ14: 0 | DA14: 0 | DB14: 0 | DC14: 0 | DD14: 0 | DE14: 0 | DF14: 0 | DG14: 0 | DH14: 0 | DI14: 0 | DJ14: 0 | DK14: 0 | DL14: 0 | DM14: 0 | DN14: 0 | DO14: 0 | DP14: 0 | DQ14: 0 | DR14: 0 | DS14: 0 | DT14: 0 | DU14: 0 | DV14: 0 | DW14: 0 | DX14: 0 | DY14: 0 | DZ14: 0 | EA14: 0 | EB14: 0 | EC14: 0 | ED14: 0 | EE14: 0 | EF14: 0 | EG14: 0 | EH14: 0 | EI14: 0 | EJ14: 0 | EK14: 0 | EL14: 0 | EM14: 0 | EN14: 0 | EO14: 0 | EP14: 0 | EQ14: 0 | ER14: 0 | ES14: 0 | ET14: 0 | EU14: 0 | EV14: 0 | EW14: 0 | EX14: 0 | EY14: 0 | EZ14: 0 | FA14: 0 | FB14: 0 | FC14: 0 | FD14: 0 | FE14: 0 | FF14: 0 | FG14: 0 | FH14: 0 | FI14: 0 | FJ14: 0 | FK14: 0 | FL14: 0 | FM14: 0 | FN14: 0 | FO14: 0 | FP14: 0 | FQ14: 0 | FR14: 0 | FS14: 0 | FT14: 0 | FU14: 0 | FV14: 0 | FW14: 0 | FX14: 0 | FY14: 0 | FZ14: 0 | GA14: 0 | GB14: 0 | GC14: 0 | GD14: =IF(AG14+AI14+AK14+A14+AM14+AO14+AQ14+AS14+AU14+AW14+AY14+BA14+BC14+BE14+BG14>0,"DATA","N/A") -> N/A | GE14: N/A | GF14: =IF(BM14+BO14+BQ14+BS14+BY14+CA14+CC14+CE14+CG14+CI14<0,"DATA","N/A") -> N/A
B15: 4 | C15: PH0100000000 | D15: PH0102800000 | E15: PH0102804000 | F15: Region I (Ilocos Region) | G15: Ilocos Norte | H15: Bangui | I15: 15227 | J15: 0 | K15: 0 | L15: 0 | M15: 0 | N15: 0 | O15: 0 | P15: 0 | Q15: 0 | R15: 0 | S15: 0 | T15: 0 | U15: 0 | V15: 0 | W15: 0 | X15: 0 | Y15: 0 | Z15: 0 | AA15: 0 | AB15: 0 | AC15: 0 | AD15: 0 | AE15: 0 | AF15: 0 | AG15: 0 | AH15: 0 | AI15: 0 | AJ15: 0 | AK15: 0 | AL15: 0 | AM15: 0 | AN15: 0 | AO15: 0 | AP15: 0 | AQ15: 0 | AR15: 0 | AS15: 0 | AT15: 0 | AU15: 0 | AV15: 0 | AW15: 0 | AX15: 0 | AY15: 0 | AZ15: 0 | BA15: 0 | BB15: 0 | BC15: 0 | BD15: 0 | BE15: 0 | BF15: 0 | BG15: 0 | BH15: 0 | BI15: 0 | BJ15: 0 | BK15: 0 | BL15: 0 | BM15: 0 | BN15: 0 | BO15: 0 | BP15: 0 | BQ15: 0 | BR15: 0 | BS15: 0 | BT15: 0 | BU15: 0 | BV15: 0 | BW15: 0 | BX15: 0 | BY15: 0 | BZ15: 0 | CA15: 0 | CB15: 0 | CC15: 0 | CD15: 0 | CE15: 0 | CF15: 0 | CG15: 0 | CH15: 0 | CI15: 0 | CJ15: 0 | CK15: 0 | CL15: 0 | CM15: 0 | CN15: 0 | CO15: 0 | CP15: 0 | CQ15: 0 | CR15: 0 | CS15: 0 | CT15: 0 | CU15: 0 | CV15: 0 | CW15: 0 | CX15: 0 | CY15: 0 | CZ15: 0 | DA15: 0 | DB15: 0 | DC15: 0 | DD15: 0 | DE15: 0 | DF15: 0 | DG15: 0 | DH15: 0 | DI15: 0 | DJ15: 0 | DK15: 0 | DL15: 0 | DM15: 0 | DN15: 0 | DO15: 0 | DP15: 0 | DQ15: 0 | DR15: 0 | DS15: 0 | DT15: 0 | DU15: 0 | DV15: 0 | DW15: 0 | DX15: 0 | DY15: 0 | DZ15: 0 | EA15: 0 | EB15: 0 | EC15: 0 | ED15: 0 | EE15: 0 | EF15: 0 | EG15: 0 | EH15: 0 | EI15: 0 | EJ15: 0 | EK15: 0 | EL15: 0 | EM15: 0 | EN15: 0 | EO15: 0 | EP15: 0 | EQ15: 0 | ER15: 0 | ES15: 0 | ET15: 0 | EU15: 0 | EV15: 0 | EW15: 0 | EX15: 0 | EY15: 0 | EZ15: 0 | FA15: 0 | FB15: 0 | FC15: 0 | FD15: 0 | FE15: 0 | FF15: 0 | FG15: 0 | FH15: 0 | FI15: 0 | FJ15: 0 | FK15: 0 | FL15: 0 | FM15: 0 | FN15: 0 | FO15: 0 | FP15: 0 | FQ15: 0 | FR15: 0 | FS15: 0 | FT15: 0 | FU15: 0 | FV15: 0 | FW15: 0 | FX15: 0 | FY15: 0 | FZ15: 0 | GA15: 0 | GB15: 0 | GC15: 0 | GD15: =IF(AG15+AI15+AK15+A15+AM15+AO15+AQ15+AS15+AU15+AW15+AY15+BA15+BC15+BE15+BG15>0,"DATA","N/A") -> N/A | GE15: N/A | GF15: =IF(BM15+BO15+BQ15+BS15+BY15+CA15+CC15+CE15+CG15+CI15<0,"DATA","N/A") -> N/A
B16: 4 | C16: PH0100000000 | D16: PH0102800000 | E16: PH0102805000 | F16: Region I (Ilocos Region) | G16: Ilocos Norte | H16: City of Batac | I16: 56781 | J16: 0 | K16: 0 | L16: 0 | M16: 0 | N16: 0 | O16: 0 | P16: 0 | Q16: 0 | R16: 0 | S16: 0 | T16: 0 | U16: 0 | V16: 0 | W16: 0 | X16: 0 | Y16: 0 | Z16: 0 | AA16: 0 | AB16: 0 | AC16: 0 | AD16: 0 | AE16: 0 | AF16: 0 | AG16: 0 | AH16: 0 | AI16: 0 | AJ16: 0 | AK16: 0 | AL16: 0 | AM16: 0 | AN16: 0 | AO16: 0 | AP16: 0 | AQ16: 0 | AR16: 0 | AS16: 0 | AT16: 0 | AU16: 0 | AV16: 0 | AW16: 0 | AX16: 0 | AY16: 0 | AZ16: 0 | BA16: 0 | BB16: 0 | BC16: 0 | BD16: 0 | BE16: 0 | BF16: 0 | BG16: 0 | BH16: 0 | BI16: 0 | BJ16: 0 | BK16: 0 | BL16: 0 | BM16: 0 | BN16: 0 | BO16: 0 | BP16: 0 | BQ16: 0 | BR16: 0 | BS16: 0 | BT16: 0 | BU16: 0 | BV16: 0 | BW16: 0 | BX16: 0 | BY16: 0 | BZ16: 0 | CA16: 0 | CB16: 0 | CC16: 0 | CD16: 0 | CE16: 0 | CF16: 0 | CG16: 0 | CH16: 0 | CI16: 0 | CJ16: 0 | CK16: 0 | CL16: 0 | CM16: 0 | CN16: 0 | CO16: 0 | CP16: 0 | CQ16: 0 | CR16: 0 | CS16: 0 | CT16: 0 | CU16: 0 | CV16: 0 | CW16: 0 | CX16: 0 | CY16: 0 | CZ16: 0 | DA16: 0 | DB16: 0 | DC16: 0 | DD16: 0 | DE16: 0 | DF16: 0 | DG16: 0 | DH16: 0 | DI16: 0 | DJ16: 0 | DK16: 0 | DL16: 0 | DM16: 0 | DN16: 0 | DO16: 0 | DP16: 0 | DQ16: 0 | DR16: 0 | DS16: 0 | DT16: 0 | DU16: 0 | DV16: 0 | DW16: 0 | DX16: 0 | DY16: 0 | DZ16: 0 | EA16: 0 | EB16: 0 | EC16: 0 | ED16: 0 | EE16: 0 | EF16: 0 | EG16: 0 | EH16: 0 | EI16: 0 | EJ16: 0 | EK16: 0 | EL16: 0 | EM16: 0 | EN16: 0 | EO16: 0 | EP16: 0 | EQ16: 0 | ER16: 0 | ES16: 0 | ET16: 0 | EU16: 0 | EV16: 0 | EW16: 0 | EX16: 0 | EY16: 0 | EZ16: 0 | FA16: 0 | FB16: 0 | FC16: 0 | FD16: 0 | FE16: 0 | FF16: 0 | FG16: 0 | FH16: 0 | FI16: 0 | FJ16: 0 | FK16: 0 | FL16: 0 | FM16: 0 | FN16: 0 | FO16: 0 | FP16: 0 | FQ16: 0 | FR16: 0 | FS16: 0 | FT16: 0 | FU16: 0 | FV16: 0 | FW16: 0 | FX16: 0 | FY16: 0 | FZ16: 0 | GA16: 0 | GB16: 0 | GC16: 0 | GD16: =IF(AG16+AI16+AK16+A16+AM16+AO16+AQ16+AS16+AU16+AW16+AY16+BA16+BC16+BE16+BG16>0,"DATA","N/A") -> N/A | GE16: N/A | GF16: =IF(BM16+BO16+BQ16+BS16+BY16+CA16+CC16+CE16+CG16+CI16<0,"DATA","N/A") -> N/A
